<robot
  name="xiaoqiang_udrf">
  <link
    name="base_link">
    <inertial>
      <origin
        xyz="-0.157602038251381 -0.00385000660473622 0.0465624701295276"
        rpy="0 0 0" />
      <mass
        value="4.77346929236529" />
      <inertia
        ixx="0.0533752323010665"
        ixy="-4.80292153681539E-05"
        ixz="-0.0152745823202864"
        iyy="0.0876189236819402"
        iyz="0.000881772892938159"
        izz="0.0799874061207763" />
    </inertial>
    <visual>
      <origin
        xyz="0 0 0"
        rpy="0 0 0" />
      <geometry>
        <mesh
          filename="package://xiaoqiang_udrf/meshes/base_link.STL" />
      </geometry>
      <material
        name="">
        <color
          rgba="0.098039 0.098039 0.098039 1" />
      </material>
    </visual>
    <collision>
      <origin
        xyz="0 0 0"
        rpy="0 0 0" />
      <geometry>
        <mesh
          filename="package://xiaoqiang_udrf/meshes/base_link.STL" />
      </geometry>
    </collision>
  </link>
  <link
    name="right_wheel">
    <inertial>
      <origin
        xyz="6.94232664757398E-05 9.3174912230154E-11 0.0293136663265149"
        rpy="0 0 0" />
      <mass
        value="0.188164864851131" />
      <inertia
        ixx="0.000228089241546029"
        ixy="-2.28556751771651E-13"
        ixz="-2.87584193050586E-07"
        iyy="0.000228397758998205"
        iyz="-6.43140750898882E-13"
        izz="0.000425379268438934" />
    </inertial>
    <visual>
      <origin
        xyz="0 0 0"
        rpy="0 0 0" />
      <geometry>
        <mesh
          filename="package://xiaoqiang_udrf/meshes/right_wheel.STL" />
      </geometry>
      <material
        name="">
        <color
          rgba="0.29412 0.29412 0.29412 1" />
      </material>
    </visual>
    <collision>
      <origin
        xyz="0 0 0"
        rpy="0 0 0" />
      <geometry>
        <mesh
          filename="package://xiaoqiang_udrf/meshes/right_wheel.STL" />
      </geometry>
    </collision>
  </link>
  <joint
    name="rot1"
    type="continuous">
    <origin
      xyz="0 -0.150112698372207 -0.06"
      rpy="1.57079632679477 1.52790873038023 -1.29473733419683E-13" />
    <parent
      link="base_link" />
    <child
      link="right_wheel" />
    <axis
      xyz="0 0 -1" />
  </joint>
  <link
    name="left_wheel">
    <inertial>
      <origin
        xyz="6.94232664756322E-05 9.31748289634271E-11 0.0293136663265147"
        rpy="0 0 0" />
      <mass
        value="0.18816486485113" />
      <inertia
        ixx="0.000228089241546028"
        ixy="-2.28556756853848E-13"
        ixz="-2.87584193050028E-07"
        iyy="0.000228397758998205"
        iyz="-6.43140070241735E-13"
        izz="0.000425379268438933" />
    </inertial>
    <visual>
      <origin
        xyz="0 0 0"
        rpy="0 0 0" />
      <geometry>
        <mesh
          filename="package://xiaoqiang_udrf/meshes/left_wheel.STL" />
      </geometry>
      <material
        name="">
        <color
          rgba="0.29412 0.29412 0.29412 1" />
      </material>
    </visual>
    <collision>
      <origin
        xyz="0 0 0"
        rpy="0 0 0" />
      <geometry>
        <mesh
          filename="package://xiaoqiang_udrf/meshes/left_wheel.STL" />
      </geometry>
    </collision>
  </link>
  <joint
    name="rot2"
    type="continuous">
    <origin
      xyz="0 0.149887301627792 -0.0599999999999983"
      rpy="-1.5707963267949 0.357463595053736 1.22790071016839E-29" />
    <parent
      link="base_link" />
    <child
      link="left_wheel" />
    <axis
      xyz="0 0 1" />
  </joint>
  <link
    name="back_wheel">
    <inertial>
      <origin
        xyz="-0.0175661121211732 -0.039912714651577 -2.47341047643346E-09"
        rpy="0 0 0" />
      <mass
        value="0.0646530070020808" />
      <inertia
        ixx="2.78414453699226E-05"
        ixy="5.75825201847833E-06"
        ixz="-4.5307195249697E-12"
        iyy="1.84347043324848E-05"
        iyz="-5.34650285838414E-12"
        izz="3.85289851904231E-05" />
    </inertial>
    <visual>
      <origin
        xyz="0 0 0"
        rpy="0 0 0" />
      <geometry>
        <mesh
          filename="package://xiaoqiang_udrf/meshes/back_wheel.STL" />
      </geometry>
      <material
        name="">
        <color
          rgba="0.29412 0.29412 0.29412 1" />
      </material>
    </visual>
    <collision>
      <origin
        xyz="0 0 0"
        rpy="0 0 0" />
      <geometry>
        <mesh
          filename="package://xiaoqiang_udrf/meshes/back_wheel.STL" />
      </geometry>
    </collision>
  </link>
  <joint
    name="rot3"
    type="continuous">
    <origin
      xyz="-0.278786796564403 -0.000112698372207953 -0.046000000000001"
      rpy="1.5707963267949 -3.45895916116442E-15 -0.160759229830102" />
    <parent
      link="base_link" />
    <child
      link="back_wheel" />
    <axis
      xyz="0 -1 0" />
  </joint>
  <link
    name="lidar_link">
    <inertial>
      <origin
        xyz="-0.000270421777020413 -0.00990182950940149 -7.10049019581049E-10"
        rpy="0 0 0" />
      <mass
        value="0.0984481070530837" />
      <inertia
        ixx="4.2386839484693E-05"
        ixy="-5.06324613218956E-08"
        ixz="-5.39378523128128E-12"
        iyy="7.73338874867687E-05"
        iyz="1.20386780457707E-11"
        izz="4.14171570330327E-05" />
    </inertial>
    <visual>
      <origin
        xyz="0 0 0"
        rpy="0 0 0" />
      <geometry>
        <mesh
          filename="package://xiaoqiang_udrf/meshes/lidar_link.STL" />
      </geometry>
      <material
        name="">
        <color
          rgba="0.29412 0.29412 0.29412 1" />
      </material>
    </visual>
    <collision>
      <origin
        xyz="0 0 0"
        rpy="0 0 0" />
      <geometry>
        <mesh
          filename="package://xiaoqiang_udrf/meshes/lidar_link.STL" />
      </geometry>
    </collision>
  </link>
  <joint
    name="rot4"
    type="continuous">
    <origin
      xyz="-0.258786796564404 6.46265772448196E-05 0.305000000000001"
      rpy="-1.5707963267949 -3.15213658012586E-15 -0.452067123629806" />
    <parent
      link="base_link" />
    <child
      link="lidar_link" />
    <axis
      xyz="0 1 0" />
  </joint>
  <link
    name="kinect_Link">
    <inertial>
      <origin
        xyz="-5.16110410976323E-05 0.004753169670485 0.0308816895381565"
        rpy="0 0 0" />
      <mass
        value="0.669252371670692" />
      <inertia
        ixx="0.000394238516303151"
        ixy="1.65888611965141E-07"
        ixz="-9.72216861979757E-07"
        iyy="0.00336084834194412"
        iyz="-3.77411822467566E-06"
        izz="0.00336614410293986" />
    </inertial>
    <visual>
      <origin
        xyz="0 0 0"
        rpy="0 0 0" />
      <geometry>
        <mesh
          filename="package://xiaoqiang_udrf/meshes/kinect_Link.STL" />
      </geometry>
      <material
        name="">
        <color
          rgba="0.29412 0.29412 0.29412 1" />
      </material>
    </visual>
    <collision>
      <origin
        xyz="0 0 0"
        rpy="0 0 0" />
      <geometry>
        <mesh
          filename="package://xiaoqiang_udrf/meshes/kinect_Link.STL" />
      </geometry>
    </collision>
  </link>
  <joint
    name="fix1"
    type="fixed">
    <origin
      xyz="-0.135557187224918 -0.000112698372204401 0.255"
      rpy="-1.57079632679489 0 -1.5707963267949" />
    <parent
      link="base_link" />
    <child
      link="kinect_Link" />
    <axis
      xyz="0 0 0" />
  </joint>
</robot>
