<robot
  name="xiaoqiang_udrf">
  <link
    name="base_link">
    <inertial>
      <origin
        xyz="0.00571229418184364 -0.000102754891326107 0.0811148502019683"
        rpy="0 0 0" />
      <mass
        value="5.51934540138491" />
      <inertia
        ixx="0.190931542400052"
        ixy="-0.000151932210553234"
        ixz="0.000218714775398145"
        iyy="0.22858847379228"
        iyz="8.03726346965803E-05"
        izz="0.336307450388486" />
    </inertial>
    <visual>
      <origin
        xyz="0 0 0"
        rpy="0 0 0" />
      <geometry>
        <mesh
          filename="package://xiaoqiang_udrf/meshes/base_link.STL" />
      </geometry>
      <material
        name="">
        <color
          rgba="1 1 1 1" />
      </material>
    </visual>
    <collision>
      <origin
        xyz="0 0 0"
        rpy="0 0 0" />
      <geometry>
        <mesh
          filename="package://xiaoqiang_udrf/meshes/base_link.STL" />
      </geometry>
    </collision>
  </link>
  <link
    name="left_wheel">
    <inertial>
      <origin
        xyz="2.427226206414E-07 -4.33570857309978E-07 -0.0314078188560065"
        rpy="0 0 0" />
      <mass
        value="0.804868654069467" />
      <inertia
        ixx="0.00126505571363722"
        ixy="-9.67257422399763E-11"
        ixz="5.19504396075941E-09"
        iyy="0.00126505539569708"
        iyz="-9.27980942972676E-09"
        izz="0.00228261521359981" />
    </inertial>
    <visual>
      <origin
        xyz="0 0 0"
        rpy="0 0 0" />
      <geometry>
        <mesh
          filename="package://xiaoqiang_udrf/meshes/left_wheel.STL" />
      </geometry>
      <material
        name="">
        <color
          rgba="0.098039 0.098039 0.098039 1" />
      </material>
    </visual>
    <collision>
      <origin
        xyz="0 0 0"
        rpy="0 0 0" />
      <geometry>
        <mesh
          filename="package://xiaoqiang_udrf/meshes/left_wheel.STL" />
      </geometry>
    </collision>
  </link>
  <joint
    name="rot1"
    type="continuous">
    <origin
      xyz="0 0.1595 -0.023"
      rpy="1.5707963267949 1.5707963267949 0" />
    <parent
      link="base_link" />
    <child
      link="left_wheel" />
    <axis
      xyz="0 0 -1" />
  </joint>
  <link
    name="right_wheel">
    <inertial>
      <origin
        xyz="2.427226206414E-07 -4.33570857289595E-07 -0.0314078188560067"
        rpy="0 0 0" />
      <mass
        value="0.804868654069467" />
      <inertia
        ixx="0.00126505571363722"
        ixy="-9.6725742243205E-11"
        ixz="5.1950439605852E-09"
        iyy="0.00126505539569708"
        iyz="-9.27980943032279E-09"
        izz="0.00228261521359981" />
    </inertial>
    <visual>
      <origin
        xyz="0 0 0"
        rpy="0 0 0" />
      <geometry>
        <mesh
          filename="package://xiaoqiang_udrf/meshes/right_wheel.STL" />
      </geometry>
      <material
        name="">
        <color
          rgba="0.098039 0.098039 0.098039 1" />
      </material>
    </visual>
    <collision>
      <origin
        xyz="0 0 0"
        rpy="0 0 0" />
      <geometry>
        <mesh
          filename="package://xiaoqiang_udrf/meshes/right_wheel.STL" />
      </geometry>
    </collision>
  </link>
  <joint
    name="rot2"
    type="continuous">
    <origin
      xyz="0 -0.1595 -0.023"
      rpy="1.5707963267949 -1.49170041722774 3.14159265358979" />
    <parent
      link="base_link" />
    <child
      link="right_wheel" />
    <axis
      xyz="0 0 1" />
  </joint>
  <link
    name="front_wheel1">
    <inertial>
      <origin
        xyz="0.0293639688147509 -0.0541914734100133 -1.1837033078721E-07"
        rpy="0 0 0" />
      <mass
        value="0.134574489008056" />
      <inertia
        ixx="9.01050497257373E-05"
        ixy="1.94978830377822E-05"
        ixz="-2.9547824252388E-10"
        iyy="6.63745101495483E-05"
        iyz="-9.21568445436582E-12"
        izz="0.00012988996922008" />
    </inertial>
    <visual>
      <origin
        xyz="0 0 0"
        rpy="0 0 0" />
      <geometry>
        <mesh
          filename="package://xiaoqiang_udrf/meshes/front_wheel1.STL" />
      </geometry>
      <material
        name="">
        <color
          rgba="0.792156862745098 0.819607843137255 0.933333333333333 1" />
      </material>
    </visual>
    <collision>
      <origin
        xyz="0 0 0"
        rpy="0 0 0" />
      <geometry>
        <mesh
          filename="package://xiaoqiang_udrf/meshes/front_wheel1.STL" />
      </geometry>
    </collision>
  </link>
  <joint
    name="rot3"
    type="continuous">
    <origin
      xyz="0.175 0.135 -0.00500000000000002"
      rpy="1.5707963267949 0 0" />
    <parent
      link="base_link" />
    <child
      link="front_wheel1" />
    <axis
      xyz="0 1 0" />
  </joint>
  <link
    name="front_wheel2">
    <inertial>
      <origin
        xyz="0.0293639688147508 -0.0541914734100133 -1.18370330801087E-07"
        rpy="0 0 0" />
      <mass
        value="0.134574489008056" />
      <inertia
        ixx="9.01050497257373E-05"
        ixy="1.94978830377824E-05"
        ixz="-2.95478242486611E-10"
        iyy="6.63745101495486E-05"
        iyz="-9.21568442387264E-12"
        izz="0.00012988996922008" />
    </inertial>
    <visual>
      <origin
        xyz="0 0 0"
        rpy="0 0 0" />
      <geometry>
        <mesh
          filename="package://xiaoqiang_udrf/meshes/front_wheel2.STL" />
      </geometry>
      <material
        name="">
        <color
          rgba="0.792156862745098 0.819607843137255 0.933333333333333 1" />
      </material>
    </visual>
    <collision>
      <origin
        xyz="0 0 0"
        rpy="0 0 0" />
      <geometry>
        <mesh
          filename="package://xiaoqiang_udrf/meshes/front_wheel2.STL" />
      </geometry>
    </collision>
  </link>
  <joint
    name="rot4"
    type="continuous">
    <origin
      xyz="0.175 -0.135 -0.005"
      rpy="1.5707963267949 0 0" />
    <parent
      link="base_link" />
    <child
      link="front_wheel2" />
    <axis
      xyz="0 1 0" />
  </joint>
  <link
    name="back_wheel1">
    <inertial>
      <origin
        xyz="0.029363968814751 -0.0541914734100133 -1.18370330842721E-07"
        rpy="0 0 0" />
      <mass
        value="0.134574489008056" />
      <inertia
        ixx="9.01050497257373E-05"
        ixy="1.94978830377821E-05"
        ixz="-2.95478242462894E-10"
        iyy="6.63745101495479E-05"
        iyz="-9.21568445267176E-12"
        izz="0.00012988996922008" />
    </inertial>
    <visual>
      <origin
        xyz="0 0 0"
        rpy="0 0 0" />
      <geometry>
        <mesh
          filename="package://xiaoqiang_udrf/meshes/back_wheel1.STL" />
      </geometry>
      <material
        name="">
        <color
          rgba="0.792156862745098 0.819607843137255 0.933333333333333 1" />
      </material>
    </visual>
    <collision>
      <origin
        xyz="0 0 0"
        rpy="0 0 0" />
      <geometry>
        <mesh
          filename="package://xiaoqiang_udrf/meshes/back_wheel1.STL" />
      </geometry>
    </collision>
  </link>
  <joint
    name="rot5"
    type="continuous">
    <origin
      xyz="-0.175 0.135 -0.00500000000000002"
      rpy="1.5707963267949 0 0" />
    <parent
      link="base_link" />
    <child
      link="back_wheel1" />
    <axis
      xyz="0 1 0" />
  </joint>
  <link
    name="back_wheel2">
    <inertial>
      <origin
        xyz="0.0293639688147508 -0.0541914734100133 -1.1837033078721E-07"
        rpy="0 0 0" />
      <mass
        value="0.134574489008056" />
      <inertia
        ixx="9.01050497257374E-05"
        ixy="1.94978830377823E-05"
        ixz="-2.95478242489999E-10"
        iyy="6.63745101495485E-05"
        iyz="-9.2156844382722E-12"
        izz="0.00012988996922008" />
    </inertial>
    <visual>
      <origin
        xyz="0 0 0"
        rpy="0 0 0" />
      <geometry>
        <mesh
          filename="package://xiaoqiang_udrf/meshes/back_wheel2.STL" />
      </geometry>
      <material
        name="">
        <color
          rgba="0.792156862745098 0.819607843137255 0.933333333333333 1" />
      </material>
    </visual>
    <collision>
      <origin
        xyz="0 0 0"
        rpy="0 0 0" />
      <geometry>
        <mesh
          filename="package://xiaoqiang_udrf/meshes/back_wheel2.STL" />
      </geometry>
    </collision>
  </link>
  <joint
    name="rot6"
    type="continuous">
    <origin
      xyz="-0.175 -0.135 -0.005"
      rpy="1.5707963267949 0 0" />
    <parent
      link="base_link" />
    <child
      link="back_wheel2" />
    <axis
      xyz="0 1 0" />
  </joint>
  <link
    name="base_Link2">
    <inertial>
      <origin
        xyz="1.05647156421126E-05 0.130320789762157 0.0552981044971211"
        rpy="0 0 0" />
      <mass
        value="0.112344913941376" />
      <inertia
        ixx="0.0034280223233624"
        ixy="3.09367042160875E-06"
        ixz="1.24973447421769E-07"
        iyy="0.00392177920837671"
        iyz="-0.000266431722395911"
        izz="0.00719827584866891" />
    </inertial>
    <visual>
      <origin
        xyz="0 0 0"
        rpy="0 0 0" />
      <geometry>
        <mesh
          filename="package://xiaoqiang_udrf/meshes/base_Link2.STL" />
      </geometry>
      <material
        name="">
        <color
          rgba="0.098039 0.098039 0.098039 1" />
      </material>
    </visual>
    <collision>
      <origin
        xyz="0 0 0"
        rpy="0 0 0" />
      <geometry>
        <mesh
          filename="package://xiaoqiang_udrf/meshes/base_Link2.STL" />
      </geometry>
    </collision>
  </link>
  <joint
    name="rot7"
    type="fixed">
    <origin
      xyz="0 0 -0.08"
      rpy="0 0 1.5707963267949" />
    <parent
      link="base_link" />
    <child
      link="base_Link2" />
    <axis
      xyz="0 0 0" />
  </joint>
</robot>
