<robot
  name="xiaoqiang_udrf">
  <link
    name="base_link">
    <inertial>
      <origin
        xyz="-0.102413099765351 -0.00179212244230441 0.0383531226057049"
        rpy="0 0 0" />
      <mass
        value="2.67497367621507" />
      <inertia
        ixx="0.0178993555148012"
        ixy="0.000209040004706242"
        ixz="-0.00590642301485839"
        iyy="0.025013649912789"
        iyz="0.00027259253698604"
        izz="0.0231817332147495" />
    </inertial>
    <visual>
      <origin
        xyz="0 0 0"
        rpy="0 0 0" />
      <geometry>
        <mesh
          filename="package://xiaoqiang_udrf/meshes/base_link.STL" />
      </geometry>
      <material
        name="">
        <color
          rgba="0.098039 0.098039 0.098039 1" />
      </material>
    </visual>
    <collision>
      <origin
        xyz="0 0 0"
        rpy="0 0 0" />
      <geometry>
        <mesh
          filename="package://xiaoqiang_udrf/meshes/base_link.STL" />
      </geometry>
    </collision>
  </link>
  <link
    name="right_wheel">
    <inertial>
      <origin
        xyz="6.942326647566E-05 9.31749399857296E-11 0.029313666326515"
        rpy="0 0 0" />
      <mass
        value="0.188164864851131" />
      <inertia
        ixx="0.000228089241546029"
        ixy="-2.28556695867476E-13"
        ixz="-2.87584193050143E-07"
        iyy="0.000228397758998205"
        iyz="-6.43140917562662E-13"
        izz="0.000425379268438934" />
    </inertial>
    <visual>
      <origin
        xyz="0 0 0"
        rpy="0 0 0" />
      <geometry>
        <mesh
          filename="package://xiaoqiang_udrf/meshes/right_wheel.STL" />
      </geometry>
      <material
        name="">
        <color
          rgba="0.29412 0.29412 0.29412 1" />
      </material>
    </visual>
    <collision>
      <origin
        xyz="0 0 0"
        rpy="0 0 0" />
      <geometry>
        <mesh
          filename="package://xiaoqiang_udrf/meshes/right_wheel.STL" />
      </geometry>
    </collision>
  </link>
  <joint
    name="rot1"
    type="continuous">
    <origin
      xyz="0 -0.105 -0.04"
      rpy="-1.5708 0.98189 -3.1416" />
    <parent
      link="base_link" />
    <child
      link="right_wheel" />
    <axis
      xyz="0 0 -1" />
  </joint>
  <link
    name="left_wheel">
    <inertial>
      <origin
        xyz="6.94232664757433E-05 9.31749399857296E-11 0.0293136663265144"
        rpy="0 0 0" />
      <mass
        value="0.188164864851131" />
      <inertia
        ixx="0.000228089241546029"
        ixy="-2.28556709420003E-13"
        ixz="-2.87584193050186E-07"
        iyy="0.000228397758998205"
        iyz="-6.43140739655385E-13"
        izz="0.000425379268438934" />
    </inertial>
    <visual>
      <origin
        xyz="0 0 0"
        rpy="0 0 0" />
      <geometry>
        <mesh
          filename="package://xiaoqiang_udrf/meshes/left_wheel.STL" />
      </geometry>
      <material
        name="">
        <color
          rgba="0.29412 0.29412 0.29412 1" />
      </material>
    </visual>
    <collision>
      <origin
        xyz="0 0 0"
        rpy="0 0 0" />
      <geometry>
        <mesh
          filename="package://xiaoqiang_udrf/meshes/left_wheel.STL" />
      </geometry>
    </collision>
  </link>
  <joint
    name="rot2"
    type="continuous">
    <origin
      xyz="0 0.105 -0.04"
      rpy="1.5708 -1.1924 -3.1416" />
    <parent
      link="base_link" />
    <child
      link="left_wheel" />
    <axis
      xyz="0 0 1" />
  </joint>
  <link
    name="back_wheel">
    <inertial>
      <origin
        xyz="-0.0175661125872034 -0.03991271523842 -2.34778087249143E-09"
        rpy="0 0 0" />
      <mass
        value="0.0646530057023567" />
      <inertia
        ixx="2.78414442568576E-05"
        ixy="5.75825101606235E-06"
        ixz="-4.28081241731912E-12"
        iyy="1.84347035627385E-05"
        iyz="-5.05214840145192E-12"
        izz="3.85289831689575E-05" />
    </inertial>
    <visual>
      <origin
        xyz="0 0 0"
        rpy="0 0 0" />
      <geometry>
        <mesh
          filename="package://xiaoqiang_udrf/meshes/back_wheel.STL" />
      </geometry>
      <material
        name="">
        <color
          rgba="0.29412 0.29412 0.29412 1" />
      </material>
    </visual>
    <collision>
      <origin
        xyz="0 0 0"
        rpy="0 0 0" />
      <geometry>
        <mesh
          filename="package://xiaoqiang_udrf/meshes/back_wheel.STL" />
      </geometry>
    </collision>
  </link>
  <joint
    name="rot3"
    type="continuous">
    <origin
      xyz="-0.145 0 -0.026"
      rpy="1.5708 6.7329E-18 -0.09469" />
    <parent
      link="base_link" />
    <child
      link="back_wheel" />
    <axis
      xyz="0 -1 0" />
  </joint>
  <link
    name="kinect_link1">
    <inertial>
      <origin
        xyz="-5.87573048013296E-05 -2.19973206316837E-11 0.00406829316587393"
        rpy="0 0 0" />
      <mass
        value="0.588695422153955" />
      <inertia
        ixx="0.000252720771288053"
        ixy="8.40537668649346E-11"
        ixz="-9.66369783165234E-07"
        iyy="0.00330215909023028"
        iyz="-8.21543916609043E-13"
        izz="0.00320599877841853" />
    </inertial>
    <visual>
      <origin
        xyz="0 0 0"
        rpy="0 0 0" />
      <geometry>
        <mesh
          filename="package://xiaoqiang_udrf/meshes/kinect_link.STL" />
      </geometry>
      <material
        name="">
        <color
          rgba="0.29412 0.29412 0.29412 1" />
      </material>
    </visual>
    <collision>
      <origin
        xyz="0 0 0"
        rpy="0 0 0" />
      <geometry>
        <mesh
          filename="package://xiaoqiang_udrf/meshes/kinect_link.STL" />
      </geometry>
    </collision>
  </link>
  <joint
    name="rot4"
    type="revolute">
    <limit upper="0.3" lower="-0.3" velocity="10" effort="10"/>
    <origin
      xyz="-0.11677 0 0.16"
      rpy="-1.6034 7.1211E-17 -1.5708" />
    <parent
      link="base_link" />
    <child
      link="kinect_link1" />
    <axis
      xyz="-1 0 0" />
    <limit
      effort="0"
      velocity="0" />
  </joint>
  <link
    name="lidar_link">
    <inertial>
      <origin
        xyz="-0.000270421777020163 -0.00990182950940148 -7.10048908558747E-10"
        rpy="0 0 0" />
      <mass
        value="0.0984481070530836" />
      <inertia
        ixx="4.2386839484693E-05"
        ixy="-5.06324613218944E-08"
        ixz="-5.39378524822194E-12"
        iyy="7.73338874867687E-05"
        iyz="1.20386780508893E-11"
        izz="4.14171570330326E-05" />
    </inertial>
    <visual>
      <origin
        xyz="0 0 0"
        rpy="0 0 0" />
      <geometry>
        <mesh
          filename="package://xiaoqiang_udrf/meshes/lidar_link.STL" />
      </geometry>
      <material
        name="">
        <color
          rgba="0.29412 0.29412 0.29412 1" />
      </material>
    </visual>
    <collision>
      <origin
        xyz="0 0 0"
        rpy="0 0 0" />
      <geometry>
        <mesh
          filename="package://xiaoqiang_udrf/meshes/lidar_link.STL" />
      </geometry>
    </collision>
  </link>
  <joint
    name="rot5"
    type="continuous">
    <origin
      xyz="-0.18 0 0.21"
      rpy="-1.5708 -4.5495E-17 2.4485" />
    <parent
      link="base_link" />
    <child
      link="lidar_link" />
    <axis
      xyz="0 1 0" />
  </joint>
</robot>
